Workbook

Sheet Gantt
A1: Smart Parking Platform – Draft Project Timeline (Gantt) – v2.0, Sep 17 2026
A2: Editable: Duration (working days) and People per task; Start dates are formulas driven by predecessors (FS = finish-to-start, SS = start-to-start). Bars redraw automatically.
K3: Sep | O3: Oct | S3: Nov | X3: Dec | AB3: Jan | AF3: Feb | AJ3: Mar | AO3: Apr
A4: ID | B4: Task / Deliverable | C4: Team | D4: People | E4: Story pts | F4: Duration (wd) | G4: Start | H4: End | I4: Predecessors | J4: Phase | K4: 46272 | L4: 46279 | M4: 46286 | N4: 46293 | O4: 46300 | P4: 46307 | Q4: 46314 | R4: 46321 | S4: 46328 | T4: 46335 | U4: 46342 | V4: 46349 | W4: 46356 | X4: 46363 | Y4: 46370 | Z4: 46377 | AA4: 46384 | AB4: 46391 | AC4: 46398 | AD4: 46405 | AE4: 46412 | AF4: 46419 | AG4: 46426 | AH4: 46433 | AI4: 46440 | AJ4: 46447 | AK4: 46454 | AL4: 46461 | AM4: 46468 | AN4: 46475 | AO4: 46482 | AP4: 46489
A5: M0 | B5: Project kickoff / contract award (SRS v1.0) | C5: PM | F5: 0 | G5: 46273 | H5: =G5 -> 46273 | J5: Milestone
A6: M1 | B6: Requirements & Design Approved | C6: Client + PM | F6: 0 | G6: =H11 -> 46311 | H6: =G6 -> 46311 | I6: P0.2 FS | J6: Milestone
A7: M2 | B7: MVP Acceptance (40% payment milestone) | C7: Client + PM | F7: 0 | G7: =H51 -> 46435 | H7: =G7 -> 46435 | I7: C1 FS | J7: Milestone
A8: M3 | B8: Beta Release (all 14 facilities, invited drivers) | C8: Client + PM | F8: 0 | G8: =H52 -> 46449 | H8: =G8 -> 46449 | I8: T2 FS | J8: Milestone
A9: M4 | B9: Final Delivery & Handover (30% payment milestone) | C9: Client + PM | F9: 0 | G9: =H53 -> 46482 | H9: =G9 -> 46482 | I9: C2 FS | J9: Milestone
A10: P0.1 | B10: Requirements finalization (SRS v1.0 -> v3.0, use cases, NFRs) | C10: PM + leads | F10: 24 | G10: 46273 | H10: =WORKDAY(G10,F10-1,Assumptions!$A$23:$A$30) -> 46304 | I10: M0 FS | J10: Phase 0
A11: P0.2 | B11: Architecture, data model and UX design | C11: Leads + UX | F11: 20 | G11: 46286 | H11: =WORKDAY(G11,F11-1,Assumptions!$A$23:$A$30) -> 46311 | I11: P0.1 SS | J11: Phase 0
A12: 1 | B12: Accounts, Authentication & Security | E12: =SUM(E13,E14,E15,E16) -> 50 | G12: =MIN(G13,G14,G15,G16) -> 46330 | H12: =MAX(H13,H14,H15,H16) -> 46370 | J12: Module summary
A13: 1.1 | B13: Driver Accounts | C13: Backend + Web | D13: 3 | E13: =WBS!D3 -> 13 | F13: =ROUNDUP(E13*Assumptions!$B$4/D13,0) -> 9 | G13: =WORKDAY(MAX(Assumptions!$B$5,WORKDAY($H$42,1,Assumptions!$A$23:$A$30))-1,1,Assumptions!$A$23:$A$30) -> 46330 | H13: =WORKDAY(G13,F13-1,Assumptions!$A$23:$A$30) -> 46342 | I13: 8.1 FS | J13: MVP scope
A14: 1.2 | B14: Operator & Administrator Access Control | C14: Backend + Web | D14: 3 | E14: =WBS!D8 -> 15 | F14: =ROUNDUP(E14*Assumptions!$B$4/D14,0) -> 10 | G14: =WORKDAY(MAX(Assumptions!$B$5,WORKDAY($H$13,1,Assumptions!$A$23:$A$30))-1,1,Assumptions!$A$23:$A$30) -> 46343 | H14: =WORKDAY(G14,F14-1,Assumptions!$A$23:$A$30) -> 46358 | I14: 1.1 FS | J14: MVP scope
A15: 1.3 | B15: Fraud & Abuse Prevention | C15: Backend | D15: 2 | E15: =WBS!D13 -> 11 | F15: =ROUNDUP(E15*Assumptions!$B$4/D15,0) -> 11 | G15: =WORKDAY(MAX(Assumptions!$B$5,WORKDAY($H$27,1,Assumptions!$A$23:$A$30),WORKDAY($H$13,1,Assumptions!$A$23:$A$30))-1,1,Assumptions!$A$23:$A$30) -> 46356 | H15: =WORKDAY(G15,F15-1,Assumptions!$A$23:$A$30) -> 46370 | I15: 4.1 FS, 1.1 FS | J15: Beta scope
A16: 1.4 | B16: Data Protection & Audit | C16: Backend | D16: 2 | E16: =WBS!D17 -> 11 | F16: =ROUNDUP(E16*Assumptions!$B$4/D16,0) -> 11 | G16: =WORKDAY(MAX(Assumptions!$B$5,$G$14)-1,1,Assumptions!$A$23:$A$30) -> 46343 | H16: =WORKDAY(G16,F16-1,Assumptions!$A$23:$A$30) -> 46359 | I16: 1.2 SS | J16: Beta scope
A17: 2 | B17: Availability, Map & Navigation | E17: =SUM(E18,E19,E20) -> 33 | G17: =MIN(G18,G19,G20) -> 46346 | H17: =MAX(H18,H19,H20) -> 46366 | J17: Module summary
A18: 2.1 | B18: Real-Time Availability Engine | C18: Backend + Mapping | D18: 3 | E18: =WBS!D22 -> 13 | F18: =ROUNDUP(E18*Assumptions!$B$4/D18,0) -> 9 | G18: =WORKDAY(MAX(Assumptions!$B$5,WORKDAY($H$43,1,Assumptions!$A$23:$A$30))-1,1,Assumptions!$A$23:$A$30) -> 46346 | H18: =WORKDAY(G18,F18-1,Assumptions!$A$23:$A$30) -> 46360 | I18: 8.2 FS | J18: MVP scope
A19: 2.2 | B19: Facility Search & Map | C19: Mapping + Mobile | D19: 4 | E19: =WBS!D26 -> 15 | F19: =ROUNDUP(E19*Assumptions!$B$4/D19,0) -> 8 | G19: =WORKDAY(MAX(Assumptions!$B$5,WORKDAY($H$45,1,Assumptions!$A$23:$A$30),$G$18)-1,1,Assumptions!$A$23:$A$30) -> 46346 | H19: =WORKDAY(G19,F19-1,Assumptions!$A$23:$A$30) -> 46359 | I19: 8.4 FS, 2.1 SS | J19: MVP scope
A20: 2.3 | B20: Navigation Hand-off | C20: Mobile | D20: 2 | E20: =WBS!D31 -> 5 | F20: =ROUNDUP(E20*Assumptions!$B$4/D20,0) -> 5 | G20: =WORKDAY(MAX(Assumptions!$B$5,WORKDAY($H$19,1,Assumptions!$A$23:$A$30))-1,1,Assumptions!$A$23:$A$30) -> 46360 | H20: =WORKDAY(G20,F20-1,Assumptions!$A$23:$A$30) -> 46366 | I20: 2.2 FS | J20: MVP scope
A21: 3 | B21: Reservations & Permits | E21: =SUM(E22,E23,E24,E25) -> 43 | G21: =MIN(G22,G23,G24,G25) -> 46392 | H21: =MAX(H22,H23,H24,H25) -> 46421 | J21: Module summary
A22: 3.1 | B22: Reservation Engine | C22: Backend + Mobile | D22: 4 | E22: =WBS!D35 -> 21 | F22: =ROUNDUP(E22*Assumptions!$B$4/D22,0) -> 11 | G22: =WORKDAY(MAX(Assumptions!$B$5,WORKDAY($H$32,1,Assumptions!$A$23:$A$30),WORKDAY($H$19,1,Assumptions!$A$23:$A$30),WORKDAY($H$27,1,Assumptions!$A$23:$A$30))-1,1,Assumptions!$A$23:$A$30) -> 46392 | H22: =WORKDAY(G22,F22-1,Assumptions!$A$23:$A$30) -> 46407 | I22: 5.2 FS, 2.2 FS, 4.1 FS | J22: MVP scope
A23: 3.2 | B23: Active Session Management | C23: Backend + Mobile | D23: 3 | E23: =WBS!D40 -> 8 | F23: =ROUNDUP(E23*Assumptions!$B$4/D23,0) -> 6 | G23: =WORKDAY(MAX(Assumptions!$B$5,WORKDAY($H$24,1,Assumptions!$A$23:$A$30))-1,1,Assumptions!$A$23:$A$30) -> 46414 | H23: =WORKDAY(G23,F23-1,Assumptions!$A$23:$A$30) -> 46421 | I23: 3.3 FS | J23: Beta scope
A24: 3.3 | B24: Entry Credentials | C24: Backend + Mobile | D24: 3 | E24: =WBS!D43 -> 6 | F24: =ROUNDUP(E24*Assumptions!$B$4/D24,0) -> 4 | G24: =WORKDAY(MAX(Assumptions!$B$5,WORKDAY($H$22,1,Assumptions!$A$23:$A$30),WORKDAY($H$43,1,Assumptions!$A$23:$A$30))-1,1,Assumptions!$A$23:$A$30) -> 46408 | H24: =WORKDAY(G24,F24-1,Assumptions!$A$23:$A$30) -> 46413 | I24: 3.1 FS, 8.2 FS | J24: MVP scope
A25: 3.4 | B25: Monthly Permits | C25: Backend + Mobile | D25: 3 | E25: =WBS!D46 -> 8 | F25: =ROUNDUP(E25*Assumptions!$B$4/D25,0) -> 6 | G25: =WORKDAY(MAX(Assumptions!$B$5,WORKDAY($H$22,1,Assumptions!$A$23:$A$30))-1,1,Assumptions!$A$23:$A$30) -> 46408 | H25: =WORKDAY(G25,F25-1,Assumptions!$A$23:$A$30) -> 46415 | I25: 3.1 FS | J25: Beta scope
A26: 4 | B26: Payments, Receipts & Finance | E26: =SUM(E27,E28,E29) -> 37 | G26: =MIN(G27,G28,G29) -> 46330 | H26: =MAX(H27,H28,H29) -> 46428 | J26: Module summary
A27: 4.1 | B27: Payment Processing | C27: Payments | D27: 2 | E27: =WBS!D50 -> 16 | F27: =ROUNDUP(E27*Assumptions!$B$4/D27,0) -> 16 | G27: =WORKDAY(MAX(Assumptions!$B$5,WORKDAY($H$42,1,Assumptions!$A$23:$A$30))-1,1,Assumptions!$A$23:$A$30) -> 46330 | H27: =WORKDAY(G27,F27-1,Assumptions!$A$23:$A$30) -> 46351 | I27: 8.1 FS | J27: MVP scope
A28: 4.2 | B28: Receipts & History | C28: Payments + Mobile | D28: 3 | E28: =WBS!D54 -> 5 | F28: =ROUNDUP(E28*Assumptions!$B$4/D28,0) -> 4 | G28: =WORKDAY(MAX(Assumptions!$B$5,WORKDAY($H$22,1,Assumptions!$A$23:$A$30))-1,1,Assumptions!$A$23:$A$30) -> 46408 | H28: =WORKDAY(G28,F28-1,Assumptions!$A$23:$A$30) -> 46413 | I28: 3.1 FS | J28: Beta scope
A29: 4.3 | B29: Finance Tools | C29: Payments + Web | D29: 3 | E29: =WBS!D57 -> 16 | F29: =ROUNDUP(E29*Assumptions!$B$4/D29,0) -> 11 | G29: =WORKDAY(MAX(Assumptions!$B$5,WORKDAY($H$28,1,Assumptions!$A$23:$A$30))-1,1,Assumptions!$A$23:$A$30) -> 46414 | H29: =WORKDAY(G29,F29-1,Assumptions!$A$23:$A$30) -> 46428 | I29: 4.2 FS | J29: Beta scope
A30: 5 | B30: Operator Dashboard & Facility Management | E30: =SUM(E31,E32,E33,E34) -> 46 | G30: =MIN(G31,G32,G33,G34) -> 46359 | H30: =MAX(H31,H32,H33,H34) -> 46422 | J30: Module summary
A31: 5.1 | B31: Facility Configuration | C31: Web + Backend | D31: 3 | E31: =WBS!D62 -> 12 | F31: =ROUNDUP(E31*Assumptions!$B$4/D31,0) -> 8 | G31: =WORKDAY(MAX(Assumptions!$B$5,WORKDAY($H$14,1,Assumptions!$A$23:$A$30))-1,1,Assumptions!$A$23:$A$30) -> 46359 | H31: =WORKDAY(G31,F31-1,Assumptions!$A$23:$A$30) -> 46370 | I31: 1.2 FS | J31: MVP scope
A32: 5.2 | B32: Pricing | C32: Web + Backend | D32: 3 | E32: =WBS!D66 -> 16 | F32: =ROUNDUP(E32*Assumptions!$B$4/D32,0) -> 11 | G32: =WORKDAY(MAX(Assumptions!$B$5,WORKDAY($H$31,1,Assumptions!$A$23:$A$30))-1,1,Assumptions!$A$23:$A$30) -> 46371 | H32: =WORKDAY(G32,F32-1,Assumptions!$A$23:$A$30) -> 46391 | I32: 5.1 FS | J32: MVP scope
A33: 5.3 | B33: Occupancy Monitoring | C33: Web + Backend | D33: 3 | E33: =WBS!D70 -> 8 | F33: =ROUNDUP(E33*Assumptions!$B$4/D33,0) -> 6 | G33: =WORKDAY(MAX(Assumptions!$B$5,WORKDAY($H$18,1,Assumptions!$A$23:$A$30),WORKDAY($H$31,1,Assumptions!$A$23:$A$30))-1,1,Assumptions!$A$23:$A$30) -> 46371 | H33: =WORKDAY(G33,F33-1,Assumptions!$A$23:$A$30) -> 46378 | I33: 2.1 FS, 5.1 FS | J33: Beta scope
A34: 5.4 | B34: Reservation Management & Lane Assist | C34: Web + Backend | D34: 3 | E34: =WBS!D73 -> 10 | F34: =ROUNDUP(E34*Assumptions!$B$4/D34,0) -> 7 | G34: =WORKDAY(MAX(Assumptions!$B$5,WORKDAY($H$24,1,Assumptions!$A$23:$A$30))-1,1,Assumptions!$A$23:$A$30) -> 46414 | H34: =WORKDAY(G34,F34-1,Assumptions!$A$23:$A$30) -> 46422 | I34: 3.3 FS | J34: Beta scope
A35: 6 | B35: Reporting & Analytics | E35: =SUM(E36,E37) -> 19 | G35: =MIN(G36,G37) -> 46363 | H35: =MAX(H36,H37) -> 46427 | J35: Module summary
A36: 6.1 | B36: Operator Reports | C36: Backend + Web | D36: 3 | E36: =WBS!D77 -> 14 | F36: =ROUNDUP(E36*Assumptions!$B$4/D36,0) -> 10 | G36: =WORKDAY(MAX(Assumptions!$B$5,WORKDAY($H$28,1,Assumptions!$A$23:$A$30),WORKDAY($H$33,1,Assumptions!$A$23:$A$30))-1,1,Assumptions!$A$23:$A$30) -> 46414 | H36: =WORKDAY(G36,F36-1,Assumptions!$A$23:$A$30) -> 46427 | I36: 4.2 FS, 5.3 FS | J36: Beta scope
A37: 6.2 | B37: Open Data | C37: Backend | D37: 2 | E37: =WBS!D81 -> 5 | F37: =ROUNDUP(E37*Assumptions!$B$4/D37,0) -> 5 | G37: =WORKDAY(MAX(Assumptions!$B$5,WORKDAY($H$18,1,Assumptions!$A$23:$A$30))-1,1,Assumptions!$A$23:$A$30) -> 46363 | H37: =WORKDAY(G37,F37-1,Assumptions!$A$23:$A$30) -> 46367 | I37: 2.1 FS | J37: Beta scope
A38: 7 | B38: Notifications | E38: =SUM(E39,E40) -> 12 | G38: =MIN(G39,G40) -> 46330 | H38: =MAX(H39,H40) -> 46346 | J38: Module summary
A39: 7.1 | B39: Notification Service | C39: Backend | D39: 2 | E39: =WBS!D84 -> 11 | F39: =ROUNDUP(E39*Assumptions!$B$4/D39,0) -> 11 | G39: =WORKDAY(MAX(Assumptions!$B$5,WORKDAY($H$42,1,Assumptions!$A$23:$A$30))-1,1,Assumptions!$A$23:$A$30) -> 46330 | H39: =WORKDAY(G39,F39-1,Assumptions!$A$23:$A$30) -> 46344 | I39: 8.1 FS | J39: MVP scope
A40: 7.2 | B40: Preferences | C40: Mobile | D40: 1 | E40: =WBS!D88 -> 1 | F40: =ROUNDUP(E40*Assumptions!$B$4/D40,0) -> 2 | G40: =WORKDAY(MAX(Assumptions!$B$5,WORKDAY($H$39,1,Assumptions!$A$23:$A$30))-1,1,Assumptions!$A$23:$A$30) -> 46345 | H40: =WORKDAY(G40,F40-1,Assumptions!$A$23:$A$30) -> 46346 | I40: 7.1 FS | J40: MVP scope
...

Sheet Assumptions
A1: Smart Parking Platform – Schedule Assumptions (v2.0 draft, HW2)
A3: Assumption | B3: Value | C3: Note
A4: Days per story point (blended developer-days) | B4: 2 | C4: 1 SP ≈ 2 developer-days incl. code review, unit tests, sprint ceremonies. Edit to re-time every task.
A5: Build start (first working day after design approval) | B5: 46314 | C5: Day after milestone M1
A6: Cushion – MVP (working days) | B6: 5 | C6: Novice-domain cushion; lecture 3 recommends 15–20% total
A7: Cushion – Final (working days) | B7: 13
A8: Integration/E2E test window (working days) | B8: 10 | C8: Applied before MVP and Beta milestones
A11: Team (from SRS §2.3; sizes assumed, unlimited budget)
A12: Team | B12: People
A13: Backend/API | B13: 6
A14: Mobile Application | B14: 3
A15: Web Application | B15: 3
A16: Mapping & Location | B16: 2
A17: Payment Integration | B17: 2
A18: QA & Testing | B18: 3
A19: Project Manager | B19: 1
A20: Total | B20: =SUM(B13:B19) -> 20
A22: Non-working days (holidays) – used by WORKDAY()
A23: 46352
A24: 46353
A25: 46380
A26: 46381
A27: 46387
A28: 46388
A29: 46405
A30: 46433
A33: Legend: blue text / yellow fill = editable input. Change a duration or the days-per-point value and all dependent dates and bars update.

Sheet WBS
A1: WBS ID | B1: Level | C1: Deliverable / Work item | D1: Story points | E1: Rationale / trace to SRS
A2: 1 | B2: 1 | C2: Accounts, Authentication & Security | D2: =D3+D8+D13+D17 -> 50 | E2: FR-1–FR-4, FR-26, NFR-7/8/15; UC-1, UC-18
A3: 1.1 | B3: 2 | C3: Driver Accounts | D3: =SUM(D4:D7) -> 13
A4: 1.1.1 | B4: 3 | C4: Email/password registration with verification code | D4: 3 | E4: UC-1 steps 1–2; standard but touches email service
A5: 1.1.2 | B5: 3 | C5: Apple and Google sign-in (OAuth) | D5: 5 | E5: Two third-party identity providers, app-store review rules
A6: 1.1.3 | B6: 3 | C6: Vehicle profiles (up to 5, default vehicle, plate-ownership check) | D6: 3 | E6: FR-2; CRUD plus duplicate-plate exception
A7: 1.1.4 | B7: 3 | C7: Password reset and account recovery | D7: 2 | E7: Well-understood pattern
A8: 1.2 | B8: 2 | C8: Operator & Administrator Access Control | D8: =SUM(D9:D12) -> 15
A9: 1.2.1 | B9: 3 | C9: Role and permission model (Operator Admin, Facility Manager, Finance, Attendant, Platform Admin) | D9: 5 | E9: FR-3; permissions scoped per facility
A10: 1.2.2 | B10: 3 | C10: Staff invitation and facility assignment | D10: 3 | E10: UC-18 steps 1–2
A11: 1.2.3 | B11: 3 | C11: Multi-factor authentication and 30-minute session expiry | D11: 5 | E11: FR-4, NFR-8; MFA provider integration
A12: 1.2.4 | B12: 3 | C12: Immediate session and API-token revocation on user removal | D12: 2 | E12: UC-18 exception
A13: 1.3 | B13: 2 | C13: Fraud & Abuse Prevention | D13: =SUM(D14:D16) -> 11
A14: 1.3.1 | B14: 3 | C14: Bot and duplicate-account defenses (rate limiting, CAPTCHA, device checks) | D14: 5 | E14: Lecture 3 'bot army' risk; unknowns in tuning
A15: 1.3.2 | B15: 3 | C15: Verified payment method with name match required before first reservation | D15: 3 | E15: Depends on 4.1; policy logic
A16: 1.3.3 | B16: 3 | C16: Per-account reservation limits and no-show rules | D16: 3 | E16: Business rules plus enforcement
A17: 1.4 | B17: 2 | C17: Data Protection & Audit | D17: =SUM(D18:D20) -> 11
A18: 1.4.1 | B18: 3 | C18: Encryption in transit (TLS 1.2+) and at rest (AES-256), key management | D18: 3 | E18: NFR-7; mostly configuration
A19: 1.4.2 | B19: 3 | C19: Personal-data export and deletion tools | D19: 3 | E19: NFR-15; touches every data store
A20: 1.4.3 | B20: 3 | C20: Audit log service with before/after values (12-month retention) | D20: 5 | E20: FR-26; cross-cutting hook into all admin actions
A21: 2 | B21: 1 | C21: Availability, Map & Navigation | D21: =D22+D26+D31 -> 33 | E21: FR-5–FR-8, NFR-1/2; UC-2, UC-4
A22: 2.1 | B22: 2 | C22: Real-Time Availability Engine | D22: =SUM(D23:D25) -> 13
A23: 2.1.1 | B23: 3 | C23: Occupancy counter service consuming gate and sensor events | D23: 8 | E23: NFR-2 5-second freshness; concurrency and event ordering risk
A24: 2.1.2 | B24: 3 | C24: 'Last updated' staleness tracking and degraded-mode flag | D24: 2 | E24: A-1 fallback
A25: 2.1.3 | B25: 3 | C25: Waitlist notification when no availability | D25: 3 | E25: UC-2 exception
A26: 2.2 | B26: 2 | C26: Facility Search & Map | D26: =SUM(D27:D30) -> 15
A27: 2.2.1 | B27: 3 | C27: Map provider integration (Google Maps Platform / Mapbox) and geocoding | D27: 5 | E27: A-4; secondary provider fallback
A28: 2.2.2 | B28: 3 | C28: Search by destination or current location with arrival time and duration | D28: 5 | E28: UC-2 steps 1–2; NFR-1 2-second target
A29: 2.2.3 | B29: 3 | C29: Filters (price, distance, covered, EV, height, 24/7) and list view | D29: 3 | E29: FR-5
A30: 2.2.4 | B30: 3 | C30: Facility detail page (photos, hours, entrance instructions) | D30: 2 | E30: UC-2 step 4
A31: 2.3 | B31: 2 | C31: Navigation Hand-off | D31: =SUM(D32:D33) -> 5
A32: 2.3.1 | B32: 3 | C32: Deep link to Google Maps, Apple Maps and Waze with entrance coordinates | D32: 3 | E32: FR-8; three platforms
A33: 2.3.2 | B33: 3 | C33: In-app fallback directions and entrance description | D33: 2 | E33: UC-4 exception
A34: 3 | B34: 1 | C34: Reservations & Permits | D34: =D35+D40+D43+D46 -> 43 | E34: FR-9–FR-13, NFR-9/13; UC-3, UC-6, UC-7, UC-9
A35: 3.1 | B35: 2 | C35: Reservation Engine | D35: =SUM(D36:D39) -> 21
A36: 3.1.1 | B36: 3 | C36: Inventory hold and double-sell prevention | D36: 8 | E36: FR-10; core transactional logic, highest business risk
A37: 3.1.2 | B37: 3 | C37: Hourly, daily and event booking flow with all-in price display | D37: 5 | E37: UC-3; NFR-9 4-tap flow
A38: 3.1.3 | B38: 3 | C38: Cancellation-policy engine and automatic refund calculation | D38: 5 | E38: FR-11; per-facility policies
A39: 3.1.4 | B39: 3 | C39: Modify or cancel reservation flow | D39: 3 | E39: UC-7
A40: 3.2 | B40: 2 | C40: Active Session Management | D40: =SUM(D41:D42) -> 8
...
